Workbook

Sheet Menu
A1: Inovação em Modelo de Negócios
A2: Um Modelo de Negócios descreve a lógica de Criação, Entrega e Captura de valor por parte de uma Organização através de 9 componentes.
A5: Seq | B5: Componente | C5: Descrição | D5: Palavras-Chave
A6: 1 | B6: Segmentos de Clientes | C6: Uma organização serve a um ou diversos Segmentos de Clientes | D6: Mercado de Massa, Nicho de Mercado, Segmento, Diversificada, Plataforma Multlateral
A7: 2 | B7: Proposta de Valor | C7: Busca resolver os problemas do Cliente e satisfazer suas necessidades, com propostas de valor. | D7: Novidade, Desempenho, Personalização, Redução de Custos, Marca, Status, Preço, Redução de Riscos, Usabilidade, Vantagem Competitiva
A8: 3 | B8: Canais | C8: As propostas de valor são levadas aos clientes por Canais de Comunicação, Distribuição e Vendas | D8: Conhecimento, Avaliação, Compra, Entrega, Pós-Venda
A9: 4 | B9: Relacionamento com Clientes | C9: O Relacionamento com Clientes é estabelecido e mantido com cada Segmento de Clientes. | D9: Conquista do Cliente, Retenção do Cliente, Ampliação de Vendas
A10: 5 | B10: Fontes de Receita | C10: As Fontes de Receita resultam de Propostas de valor oferecidas com sucesso aos Clientes | D10: Venda de Recursos, Taxa de Assinatura, Taxa de Uso, Licenciamento, Mecanismos de Precificação Fixa ou Dinâmica
A11: 6 | B11: Recursos Principais | C11: Os Recursos Principais descreve os recursos mais importantes exigidos para fazer um Modelo de Negócios funcionar. | D11: Físico, Intelectual, Humano, Financeiro, Patentes
A12: 7 | B12: Atividades-Chave | C12: A Atividades-chave descreve as ações mais importantes que uma empresa deve realizar para fazer o Modelo Funcionar | D12: Produção, Resolução de Problemas, Backoffice, Marketing, Comercial
A13: 8 | B13: Parcerias Principais | C13: Algumas atividades são terceirizados e alguns recursos são adquiridas fora da empresa | D13: Otimização e Economia de Escala, Redução de Riscos e incerteza, Aquisição de Recursos, Joint-Venture para novos negócios, Consultores, Especialistas
A14: 9 | B14: Estrutura de Custos | C14: A Estrutura de Custo descreve todos os custos envolvidos na Operação de um Modelo de Negócios | D14: Custos Fixos, Custos Variáveis, Economia de Escala

Sheet GestaoDeRisco
A1: Gestão de Riscos
A2: Id | B2: Data | C2: Autor | D2: Risco | E2: Mitigação | F2: Tipo | G2: Probabilidade | H2: Impacto | I2: Severidade
A3: 1 | B3: 43892 | C3: Tom | D3: A utilização de linguagens de Programação com baixo conhecimento no mercado pode prejudicar a busca por profissionais | E3: Utilizar linguagens com alta disponibilidade de especialista no Mercado | F3: Tecnologia | G3: 3-Alto | H3: 2-Medio | I3: =LEFT(G3,1)*LEFT(H3,1) -> 6
A4: 2 | B4: 43892 | C4: Hugo | D4: Falta de definição clara do Tipo de Solução que sera ofertada: Software, Hardware, Consultoria podera confundir a cabeça do Investidores e demais integrantes do grupo. | E4: Fazer uma declaração de Missão com foco no Objetivo da Padaria 4.0 e visão para 3 anos (ou mais). | F4: Negócio | G4: 2-Medio | H4: 3-Alto | I4: =LEFT(G4,1)*LEFT(H4,1) -> 6
A5: 3 | B5: 43892 | C5: Tom | D5: Na tercerização do DEV, alguem pode "roubar" a ideia e vender para outras pessoas (ou até mesmo implementar) | E5: Criar arquitetura de forma modular no melhor estilo "lego" e fatiar o DEV em várias fábricas de software (ou desenvolvedores "freelas"). Ex: BlueCore, Workana etc. | F5: Negócio | G5: 3-Alto | H5: 3-Alto | I5: =LEFT(G5,1)*LEFT(H5,1) -> 9
A6: 4 | B6: 43893 | C6: Tom | D6: Falta de mdo especializada nas Padarias para auxiliar na implantação do Produto Padaria 4.0. pode retardar o crescimento. | E6: Aplicação da Adoção de Tecnologia para os profissionais da Padaria. Desenvolver Tecnologia de Inteligencia Artifical para ajudar na capacitação de pessoas. | F6: Pessoa | G6: 3-Alto | H6: 2-Medio | I6: =LEFT(G6,1)*LEFT(H6,1) -> 6
A7: 5 | B7: 43893 | C7: Tom | D7: LGPD poderá comprometer pela restrição de troca de informações para alimentar as analises | E7: Contrato entre Results e Padaria para suportar esta troca de informações. Outro ponto é trabalhar com amostragem para não identificar a pessoa fisica. | F7: Negócio | G7: 3-Alto | H7: 1-Baixo | I7: =LEFT(G7,1)*LEFT(H7,1) -> 3
A8: 6 | B8: 43922 | C8: Hugo | D8: Resistência a implementação de novas tecnologias | E8: ????????? | F8: Pessoa | G8: 3-Alto | H8: 3-Alto | I8: =LEFT(G8,1)*LEFT(H8,1) -> 9
A9: 7 | I9: =LEFT(G9,1)*LEFT(H9,1) -> 0
A10: 8 | I10: =LEFT(G10,1)*LEFT(H10,1) -> 0
A11: 9 | I11: =LEFT(G11,1)*LEFT(H11,1) -> 0
A12: 10 | I12: =LEFT(G12,1)*LEFT(H12,1) -> 0
A13: 11 | I13: =LEFT(G13,1)*LEFT(H13,1) -> 0
A14: 12 | I14: =LEFT(G14,1)*LEFT(H14,1) -> 0
A15: 13 | I15: =LEFT(G15,1)*LEFT(H15,1) -> 0
A16: 14 | I16: =LEFT(G16,1)*LEFT(H16,1) -> 0
A17: 15 | I17: =LEFT(G17,1)*LEFT(H17,1) -> 0
A18: 16 | I18: =LEFT(G18,1)*LEFT(H18,1) -> 0

Sheet BluePrint_Dashboard
A1: Dashboard do Blueprint para entender o GAP da solução desejada e definir um Plano de Ação

Sheet BluePrint
A1: BluePrint: Mapeamento do Cenário Atual (AS IS) X Futuro (TO BE)
A2: Id | B2: Resp | C2: Requisito_De_Negócio | D2: Requisito_Tecnico | E2: Entrega de Valor | F2: PercPronto | G2: Tecnologia | H2: Status | I2: Prioridade
A3: 1 | B3: Jefferson | C3: Melhorar a Experiência do Cliente c/ Ominichannel | D3: R-Voip | E3: Aumentar o alcance para meus clientes | F3: =IFERROR(VLOOKUP(D3,Produtos_Results!$A$2:$E$22,5),"") -> 0.85714286 | H3: Concluído | I3: 4-Quick Wins
A4: 2 | B4: Jefferson | C4: Melhorar a Experiência do Cliente c/ Ominichannel | D4: R-Cloud | F4: =IFERROR(VLOOKUP(D4,Produtos_Results!$A$2:$E$22,5),"") -> 0 | H4: Andamento | I4: 4-Quick Wins
A5: 3 | B5: Jefferson | C5: Melhorar a Experiência do Cliente c/ Ominichannel | D5: R-Virtu | F5: =IFERROR(VLOOKUP(D5,Produtos_Results!$A$2:$E$22,5),"") -> 0 | H5: Pendente | I5: 3-Short Term
A6: 4 | B6: Jefferson | C6: Melhorar a Experiência do Cliente c/ Ominichannel | D6: R-Conf | F6: =IFERROR(VLOOKUP(D6,Produtos_Results!$A$2:$E$22,5),"") -> 0.5 | H6: Andamento | I6: 2-Medium Term
A7: 5 | B7: Jefferson | C7: Melhorar a Experiência do Cliente c/ Ominichannel | D7: R-Delivery | F7: =IFERROR(VLOOKUP(D7,Produtos_Results!$A$2:$E$22,5),"") -> 0 | H7: Pendente | I7: 4-Quick Wins
A8: 6 | B8: Jefferson | C8: Aumentar a Retenção de Clientes | D8: R-Cloud | F8: =IFERROR(VLOOKUP(D8,Produtos_Results!$A$2:$E$22,5),"") -> 0 | H8: Andamento | I8: 4-Quick Wins
A9: 7 | B9: Jefferson | C9: Aumentar a Retenção de Clientes | D9: R-Voip | E9: Melhorar a comunicação com os clientes | F9: =IFERROR(VLOOKUP(D9,Produtos_Results!$A$2:$E$22,5),"") -> 0.85714286 | H9: Concluído | I9: 4-Quick Wins
A10: 8 | B10: Jefferson | C10: Aumentar a Retenção de Clientes | D10: R-Conf | F10: =IFERROR(VLOOKUP(D10,Produtos_Results!$A$2:$E$22,5),"") -> 0.5 | H10: Andamento | I10: 2-Medium Term
A11: 9 | B11: Jefferson | C11: Aumentar a Retenção de Clientes | D11: R-Virtu | F11: =IFERROR(VLOOKUP(D11,Produtos_Results!$A$2:$E$22,5),"") -> 0 | H11: Pendente | I11: 3-Short Term
A12: 10 | B12: Jefferson | C12: Aumentar a Retenção de Clientes | D12: R-BI | F12: =IFERROR(VLOOKUP(D12,Produtos_Results!$A$2:$E$22,5),"") -> 0 | H12: Pendente | I12: 4-Quick Wins
A13: 11 | B13: Jefferson | C13: Identificar gargalos na Cadeira Produtiva | D13: R-Voip | F13: =IFERROR(VLOOKUP(D13,Produtos_Results!$A$2:$E$22,5),"") -> 0.85714286 | H13: Concluído | I13: 3-Short Term
A14: 12 | B14: Jefferson | C14: Identificar gargalos na Cadeira Produtiva | D14: R-Cloud | F14: =IFERROR(VLOOKUP(D14,Produtos_Results!$A$2:$E$22,5),"") -> 0 | H14: Andamento | I14: 4-Quick Wins
A15: 13 | B15: Jefferson | C15: Identificar gargalos na Cadeira Produtiva | D15: R-Virtu | F15: =IFERROR(VLOOKUP(D15,Produtos_Results!$A$2:$E$22,5),"") -> 0 | H15: Pendente | I15: 4-Quick Wins
A16: 14 | B16: Jefferson | C16: Identificar gargalos na Cadeira Produtiva | D16: R-Conf | F16: =IFERROR(VLOOKUP(D16,Produtos_Results!$A$2:$E$22,5),"") -> 0.5 | H16: Andamento | I16: 3-Short Term
A17: 15 | B17: Jefferson | C17: Identificar gargalos na Cadeira Produtiva | D17: R-N0 | F17: =IFERROR(VLOOKUP(D17,Produtos_Results!$A$2:$E$22,5),"") -> 0.85714286 | H17: Concluído | I17: 3-Short Term
A18: 16 | B18: Jefferson | C18: Identificar gargalos na Cadeira Produtiva | D18: R-Drive | F18: =IFERROR(VLOOKUP(D18,Produtos_Results!$A$2:$E$22,5),"") -> 0.25 | H18: Andamento | I18: 4-Quick Wins
A19: 17 | B19: Jefferson | C19: Identificar gargalos na Cadeira Produtiva | D19: R-BI | F19: =IFERROR(VLOOKUP(D19,Produtos_Results!$A$2:$E$22,5),"") -> 0 | H19: Pendente | I19: 2-Medium Term
A20: 18 | B20: Jefferson | C20: Diminuir riscos operacionais | D20: R-N0 | F20: =IFERROR(VLOOKUP(D20,Produtos_Results!$A$2:$E$22,5),"") -> 0.85714286 | H20: Concluído | I20: 4-Quick Wins
A21: 19 | B21: Jefferson | C21: Diminuir riscos operacionais | D21: R-Cloud | F21: =IFERROR(VLOOKUP(D21,Produtos_Results!$A$2:$E$22,5),"") -> 0 | H21: Andamento | I21: 4-Quick Wins
A22: 20 | B22: Jefferson | C22: Diminuir riscos operacionais | D22: R-Voip | E22: Aumentar a disponibilidade da telefonia | F22: =IFERROR(VLOOKUP(D22,Produtos_Results!$A$2:$E$22,5),"") -> 0.85714286 | H22: Concluído | I22: 4-Quick Wins
A23: 21 | B23: Jefferson | C23: Diminuir riscos operacionais | D23: R-Virtu | F23: =IFERROR(VLOOKUP(D23,Produtos_Results!$A$2:$E$22,5),"") -> 0 | H23: Pendente | I23: 4-Quick Wins
A24: 22 | B24: Jefferson | C24: Diminuir riscos operacionais | D24: R-Drive | F24: =IFERROR(VLOOKUP(D24,Produtos_Results!$A$2:$E$22,5),"") -> 0.25 | H24: Andamento | I24: 4-Quick Wins
A25: 23 | B25: Jefferson | C25: Implementar Dashboard com KPI's do negocio | D25: R-BI | F25: =IFERROR(VLOOKUP(D25,Produtos_Results!$A$2:$E$22,5),"") -> 0 | H25: Pendente | I25: 4-Quick Wins
A26: 24 | B26: Jefferson | C26: Implementar Dashboard com KPI's do negocio | D26: R-Delivery | F26: =IFERROR(VLOOKUP(D26,Produtos_Results!$A$2:$E$22,5),"") -> 0 | H26: Pendente | I26: 3-Short Term
A27: 25 | B27: Jefferson | C27: Implementar Dashboard com KPI's do negocio | D27: R-PDV | F27: =IFERROR(VLOOKUP(D27,Produtos_Results!$A$2:$E$22,5),"") -> 0 | H27: Pendente | I27: 3-Short Term
A28: 26 | B28: Jefferson | C28: Implementar Dashboard com KPI's do negocio | D28: R-ERP | F28: =IFERROR(VLOOKUP(D28,Produtos_Results!$A$2:$E$22,5),"") -> 0.5 | H28: Andamento | I28: 4-Quick Wins
A29: 27 | B29: Jefferson | C29: Implementar Dashboard com KPI's do negocio | D29: R-Virtu | F29: =IFERROR(VLOOKUP(D29,Produtos_Results!$A$2:$E$22,5),"") -> 0 | H29: Pendente | I29: 4-Quick Wins
A30: 28 | B30: Jefferson | C30: Implementar Dashboard com KPI's do negocio | D30: R-Cloud | F30: =IFERROR(VLOOKUP(D30,Produtos_Results!$A$2:$E$22,5),"") -> 0 | H30: Andamento | I30: 3-Short Term
A31: 29 | B31: Jefferson | C31: Melhorar a Experiência do Cliente c/ Ominichannel | D31: R-Fone | F31: =IFERROR(VLOOKUP(D31,Produtos_Results!$A$2:$E$22,5),"") -> 0.75 | H31: Pendente | I31: 1-Extend Term
A32: 30 | B32: Jefferson | C32: Melhorar a Experiência do Cliente c/ Ominichannel | D32: R-Voice | F32: =IFERROR(VLOOKUP(D32,Produtos_Results!$A$2:$E$22,5),"") -> 0.66666667 | H32: Pendente | I32: 1-Extend Term
A33: 31 | B33: Jefferson | C33: Melhorar a Experiência do Cliente c/ Ominichannel | D33: RIA | F33: =IFERROR(VLOOKUP(D33,Produtos_Results!$A$2:$E$22,5),"") -> 0 | G33: Phyton | H33: Pendente | I33: 1-Extend Term
A34: 32 | B34: Jefferson | C34: Aumentar a Retenção de Clientes | D34: R-Fone | F34: =IFERROR(VLOOKUP(D34,Produtos_Results!$A$2:$E$22,5),"") -> 0.75 | H34: Pendente | I34: 1-Extend Term
A35: 33 | B35: Jefferson | C35: Aumentar a Retenção de Clientes | D35: R-Voice | F35: =IFERROR(VLOOKUP(D35,Produtos_Results!$A$2:$E$22,5),"") -> 0.66666667 | H35: Pendente | I35: 1-Extend Term
A36: 34 | B36: Jefferson | C36: Aumentar a Retenção de Clientes | D36: RIA | F36: =IFERROR(VLOOKUP(D36,Produtos_Results!$A$2:$E$22,5),"") -> 0 | H36: Pendente | I36: 1-Extend Term
A37: 35 | B37: Jefferson | C37: Identificar gargalos na Cadeira Produtiva | D37: R-Fone | F37: =IFERROR(VLOOKUP(D37,Produtos_Results!$A$2:$E$22,5),"") -> 0.75 | H37: Pendente | I37: 1-Extend Term
A38: 36 | B38: Jefferson | C38: Identificar gargalos na Cadeira Produtiva | D38: R-Voice | F38: =IFERROR(VLOOKUP(D38,Produtos_Results!$A$2:$E$22,5),"") -> 0.66666667 | H38: Pendente | I38: 1-Extend Term
A39: 37 | B39: Jefferson | C39: Identificar gargalos na Cadeira Produtiva | D39: RIA | F39: =IFERROR(VLOOKUP(D39,Produtos_Results!$A$2:$E$22,5),"") -> 0 | H39: Pendente | I39: 1-Extend Term
A40: 38 | B40: Jefferson | C40: Diminuir riscos operacionais | D40: R-Fone | F40: =IFERROR(VLOOKUP(D40,Produtos_Results!$A$2:$E$22,5),"") -> 0.75 | H40: Pendente | I40: 1-Extend Term
...

Sheet Produtos_Results
A1: Tabela de Produtos da Results
A2: Sigla | B2: Descrição | C2: Tot_Func | D2: Func_OK | E2: PercPronto | F2: Observação
A3: R-BI | B3: Plataforma de Business Intelligence | C3: =IFERROR(COUNTIF(Produtos_X_Funcionalidades!$B$3:$B$62,A3),0) -> 0 | D3: =IFERROR(COUNTIFS(Produtos_X_Funcionalidades!$B$3:$B$62,A3,Produtos_X_Funcionalidades!$F$3:$F$62,"Concluído"),0) -> 0 | E3: =IFERROR(COUNTIFS(Produtos_X_Funcionalidades!$B$3:$B$62,A3,Produtos_X_Funcionalidades!$F$3:$F$62,"Concluído")/C3,0) -> 0 | F3: Permite a elaboração de vários relatórios e dashboards com recurso de drill-down
A4: R-Cloud | B4: Integrado de Clouds | C4: =IFERROR(COUNTIF(Produtos_X_Funcionalidades!$B$3:$B$62,A4),0) -> 0 | D4: =IFERROR(COUNTIFS(Produtos_X_Funcionalidades!$B$3:$B$62,A4,Produtos_X_Funcionalidades!$F$3:$F$62,"Concluído"),0) -> 0 | E4: =IFERROR(COUNTIFS(Produtos_X_Funcionalidades!$B$3:$B$62,A4,Produtos_X_Funcionalidades!$F$3:$F$62,"Concluído")/C4,0) -> 0 | F4: Permite integrar a cloud de results com cloud de terceiros (API, Webservice, Socket)
A5: R-Conf | B5: Solução de Conferencia | C5: =IFERROR(COUNTIF(Produtos_X_Funcionalidades!$B$3:$B$62,A5),0) -> 4 | D5: =IFERROR(COUNTIFS(Produtos_X_Funcionalidades!$B$3:$B$62,A5,Produtos_X_Funcionalidades!$F$3:$F$62,"Concluído"),0) -> 2 | E5: =IFERROR(COUNTIFS(Produtos_X_Funcionalidades!$B$3:$B$62,A5,Produtos_X_Funcionalidades!$F$3:$F$62,"Concluído")/C5,0) -> 0.5
A6: R-Delivery | B6: Solução de Service Desk | C6: =IFERROR(COUNTIF(Produtos_X_Funcionalidades!$B$3:$B$62,A6),0) -> 0 | D6: =IFERROR(COUNTIFS(Produtos_X_Funcionalidades!$B$3:$B$62,A6,Produtos_X_Funcionalidades!$F$3:$F$62,"Concluído"),0) -> 0 | E6: =IFERROR(COUNTIFS(Produtos_X_Funcionalidades!$B$3:$B$62,A6,Produtos_X_Funcionalidades!$F$3:$F$62,"Concluído")/C6,0) -> 0
A7: R-Drive | B7: Gerenciador de Periféricos | C7: =IFERROR(COUNTIF(Produtos_X_Funcionalidades!$B$3:$B$62,A7),0) -> 8 | D7: =IFERROR(COUNTIFS(Produtos_X_Funcionalidades!$B$3:$B$62,A7,Produtos_X_Funcionalidades!$F$3:$F$62,"Concluído"),0) -> 2 | E7: =IFERROR(COUNTIFS(Produtos_X_Funcionalidades!$B$3:$B$62,A7,Produtos_X_Funcionalidades!$F$3:$F$62,"Concluído")/C7,0) -> 0.25 | F7: Permite a comunicação e integração de vários periféricos através de LAN
A8: R-ERP | B8: Gerenciador de ERP | C8: =IFERROR(COUNTIF(Produtos_X_Funcionalidades!$B$3:$B$62,A8),0) -> 4 | D8: =IFERROR(COUNTIFS(Produtos_X_Funcionalidades!$B$3:$B$62,A8,Produtos_X_Funcionalidades!$F$3:$F$62,"Concluído"),0) -> 2 | E8: =IFERROR(COUNTIFS(Produtos_X_Funcionalidades!$B$3:$B$62,A8,Produtos_X_Funcionalidades!$F$3:$F$62,"Concluído")/C8,0) -> 0.5 | F8: Permite integração com diversos ERP do mercado
A9: R-Fone | B9: Solução de Softphone | C9: =IFERROR(COUNTIF(Produtos_X_Funcionalidades!$B$3:$B$62,A9),0) -> 8 | D9: =IFERROR(COUNTIFS(Produtos_X_Funcionalidades!$B$3:$B$62,A9,Produtos_X_Funcionalidades!$F$3:$F$62,"Concluído"),0) -> 6 | E9: =IFERROR(COUNTIFS(Produtos_X_Funcionalidades!$B$3:$B$62,A9,Produtos_X_Funcionalidades!$F$3:$F$62,"Concluído")/C9,0) -> 0.75
A10: R-N0 | B10: Gerenciador de Falhas | C10: =IFERROR(COUNTIF(Produtos_X_Funcionalidades!$B$3:$B$62,A10),0) -> 7 | D10: =IFERROR(COUNTIFS(Produtos_X_Funcionalidades!$B$3:$B$62,A10,Produtos_X_Funcionalidades!$F$3:$F$62,"Concluído"),0) -> 6 | E10: =IFERROR(COUNTIFS(Produtos_X_Funcionalidades!$B$3:$B$62,A10,Produtos_X_Funcionalidades!$F$3:$F$62,"Concluído")/C10,0) -> 0.85714286 | F10: Permite o Monitoramento, Diagnóstico, Aviso e resolução
A11: R-PDV | B11: Gerenciador de PDV | C11: =IFERROR(COUNTIF(Produtos_X_Funcionalidades!$B$3:$B$62,A11),0) -> 0 | D11: =IFERROR(COUNTIFS(Produtos_X_Funcionalidades!$B$3:$B$62,A11,Produtos_X_Funcionalidades!$F$3:$F$62,"Concluído"),0) -> 0 | E11: =IFERROR(COUNTIFS(Produtos_X_Funcionalidades!$B$3:$B$62,A11,Produtos_X_Funcionalidades!$F$3:$F$62,"Concluído")/C11,0) -> 0 | F11: Permite integração com diversos PDV do mercado
A12: R-Print | B12: Gerenciador de Impressão | C12: =IFERROR(COUNTIF(Produtos_X_Funcionalidades!$B$3:$B$62,A12),0) -> 6 | D12: =IFERROR(COUNTIFS(Produtos_X_Funcionalidades!$B$3:$B$62,A12,Produtos_X_Funcionalidades!$F$3:$F$62,"Concluído"),0) -> 0 | E12: =IFERROR(COUNTIFS(Produtos_X_Funcionalidades!$B$3:$B$62,A12,Produtos_X_Funcionalidades!$F$3:$F$62,"Concluído")/C12,0) -> 0 | F12: Permite a integração com outros periféricos e impressão de dados (ex: Etiquetas da balança)
A13: R-Virtu | B13: Assistente Virtual | C13: =IFERROR(COUNTIF(Produtos_X_Funcionalidades!$B$3:$B$62,A13),0) -> 0 | D13: =IFERROR(COUNTIFS(Produtos_X_Funcionalidades!$B$3:$B$62,A13,Produtos_X_Funcionalidades!$F$3:$F$62,"Concluído"),0) -> 0 | E13: =IFERROR(COUNTIFS(Produtos_X_Funcionalidades!$B$3:$B$62,A13,Produtos_X_Funcionalidades!$F$3:$F$62,"Concluído")/C13,0) -> 0 | F13: Permite a Automatização de Processos
A14: R-Voice | B14: Solução de Voice | C14: =IFERROR(COUNTIF(Produtos_X_Funcionalidades!$B$3:$B$62,A14),0) -> 9 | D14: =IFERROR(COUNTIFS(Produtos_X_Funcionalidades!$B$3:$B$62,A14,Produtos_X_Funcionalidades!$F$3:$F$62,"Concluído"),0) -> 6 | E14: =IFERROR(COUNTIFS(Produtos_X_Funcionalidades!$B$3:$B$62,A14,Produtos_X_Funcionalidades!$F$3:$F$62,"Concluído")/C14,0) -> 0.66666667
A15: R-Voip | B15: Gerenciador de Chamadas | C15: =IFERROR(COUNTIF(Produtos_X_Funcionalidades!$B$3:$B$62,A15),0) -> 14 | D15: =IFERROR(COUNTIFS(Produtos_X_Funcionalidades!$B$3:$B$62,A15,Produtos_X_Funcionalidades!$F$3:$F$62,"Concluído"),0) -> 12 | E15: =IFERROR(COUNTIFS(Produtos_X_Funcionalidades!$B$3:$B$62,A15,Produtos_X_Funcionalidades!$F$3:$F$62,"Concluído")/C15,0) -> 0.85714286 | F15: Sistema de Call-Center que converte voz em dados e vice-versa
A16: RIA | B16: Plataforma de Inteligencial Artificial | C16: =IFERROR(COUNTIF(Produtos_X_Funcionalidades!$B$3:$B$62,A16),0) -> 0 | D16: =IFERROR(COUNTIFS(Produtos_X_Funcionalidades!$B$3:$B$62,A16,Produtos_X_Funcionalidades!$F$3:$F$62,"Concluído"),0) -> 0 | E16: =IFERROR(COUNTIFS(Produtos_X_Funcionalidades!$B$3:$B$62,A16,Produtos_X_Funcionalidades!$F$3:$F$62,"Concluído")/C16,0) -> 0 | F16: Permite o desenvolvimento de Tecnologia de Transformação Digital âncorados em Inteligência Artificial
C17: =IFERROR(COUNTIF(Produtos_X_Funcionalidades!$B$3:$B$62,A17),0) -> 0 | D17: =IFERROR(COUNTIFS(Produtos_X_Funcionalidades!$B$3:$B$62,A17,Produtos_X_Funcionalidades!$F$3:$F$62,"Concluído"),0) -> 0 | E17: =IFERROR(COUNTIFS(Produtos_X_Funcionalidades!$B$3:$B$62,A17,Produtos_X_Funcionalidades!$F$3:$F$62,"Concluído")/C17,0) -> 0
C18: =IFERROR(COUNTIF(Produtos_X_Funcionalidades!$B$3:$B$62,A18),0) -> 0 | D18: =IFERROR(COUNTIFS(Produtos_X_Funcionalidades!$B$3:$B$62,A18,Produtos_X_Funcionalidades!$F$3:$F$62,"Concluído"),0) -> 0 | E18: =IFERROR(COUNTIFS(Produtos_X_Funcionalidades!$B$3:$B$62,A18,Produtos_X_Funcionalidades!$F$3:$F$62,"Concluído")/C18,0) -> 0
C19: =IFERROR(COUNTIF(Produtos_X_Funcionalidades!$B$3:$B$62,A19),0) -> 0 | D19: =IFERROR(COUNTIFS(Produtos_X_Funcionalidades!$B$3:$B$62,A19,Produtos_X_Funcionalidades!$F$3:$F$62,"Concluído"),0) -> 0 | E19: =IFERROR(COUNTIFS(Produtos_X_Funcionalidades!$B$3:$B$62,A19,Produtos_X_Funcionalidades!$F$3:$F$62,"Concluído")/C19,0) -> 0
C20: =IFERROR(COUNTIF(Produtos_X_Funcionalidades!$B$3:$B$62,A20),0) -> 0 | D20: =IFERROR(COUNTIFS(Produtos_X_Funcionalidades!$B$3:$B$62,A20,Produtos_X_Funcionalidades!$F$3:$F$62,"Concluído"),0) -> 0 | E20: =IFERROR(COUNTIFS(Produtos_X_Funcionalidades!$B$3:$B$62,A20,Produtos_X_Funcionalidades!$F$3:$F$62,"Concluído")/C20,0) -> 0
C21: =IFERROR(COUNTIF(Produtos_X_Funcionalidades!$B$3:$B$62,A21),0) -> 0 | D21: =IFERROR(COUNTIFS(Produtos_X_Funcionalidades!$B$3:$B$62,A21,Produtos_X_Funcionalidades!$F$3:$F$62,"Concluído"),0) -> 0 | E21: =IFERROR(COUNTIFS(Produtos_X_Funcionalidades!$B$3:$B$62,A21,Produtos_X_Funcionalidades!$F$3:$F$62,"Concluído")/C21,0) -> 0
C22: =IFERROR(COUNTIF(Produtos_X_Funcionalidades!$B$3:$B$62,A22),0) -> 0 | D22: =IFERROR(COUNTIFS(Produtos_X_Funcionalidades!$B$3:$B$62,A22,Produtos_X_Funcionalidades!$F$3:$F$62,"Concluído"),0) -> 0 | E22: =IFERROR(COUNTIFS(Produtos_X_Funcionalidades!$B$3:$B$62,A22,Produtos_X_Funcionalidades!$F$3:$F$62,"Concluído")/C22,0) -> 0

Sheet Apresentação do Jeferson-Miguel
A1: Id | B1: Item | C1: Tecnologia
A2: 1 | B2: Aplicativo que vai integrar com Balança | C2: IoT
A3: 2 | B3: Websocket | C3: IoT

Sheet Produtos_X_Funcionalidades
A1: Relação de Produtos X Funcionalidades
A2: Id | B2: Produtos | C2: PercPronto | D2: Descrição | E2: Funcionalidade | F2: Status | G2: Observação
A3: 1 | B3: R-ERP | C3: =IFERROR(VLOOKUP(B3,Produtos_Results!$A$2:$E$22,5),"") -> 0.5 | D3: =IFERROR(VLOOKUP(B3,Produtos_Results!$A$3:$B$22,2,FALSE),"") -> Gerenciador de ERP | E3: Integração com SAP | F3: Concluído | G3: Funcionalidade ja testada em produção com no Cliente Padaria do Ze
A4: 2 | B4: R-ERP | C4: =IFERROR(VLOOKUP(B4,Produtos_Results!$A$2:$E$22,5),"") -> 0.5 | D4: =IFERROR(VLOOKUP(B4,Produtos_Results!$A$3:$B$22,2,FALSE),"") -> Gerenciador de ERP | E4: Integração com TOTVs | F4: Andamento | G4: Em fase de desenvolvimento do WebService, Layout já definido.
A5: 3 | B5: R-ERP | C5: =IFERROR(VLOOKUP(B5,Produtos_Results!$A$2:$E$22,5),"") -> 0.5 | D5: =IFERROR(VLOOKUP(B5,Produtos_Results!$A$3:$B$22,2,FALSE),"") -> Gerenciador de ERP | E5: Integração com Senior Sistemas | F5: Pendente | G5: Aguardar Cliente com este perfil para iniciar DEV
A6: 4 | B6: R-ERP | C6: =IFERROR(VLOOKUP(B6,Produtos_Results!$A$2:$E$22,5),"") -> 0.5 | D6: =IFERROR(VLOOKUP(B6,Produtos_Results!$A$3:$B$22,2,FALSE),"") -> Gerenciador de ERP | E6: Integração com Benner | F6: Concluído | G6: Funcionalidade ja testada em produção com no Cliente Padaria do João
A7: 5 | B7: R-Voip | C7: =IFERROR(VLOOKUP(B7,Produtos_Results!$A$2:$E$22,5),"") -> 0.85714286 | D7: =IFERROR(VLOOKUP(B7,Produtos_Results!$A$3:$B$22,2,FALSE),"") -> Gerenciador de Chamadas | E7: Chamadas pela internet | F7: Concluído
A8: 6 | B8: R-Voip | C8: =IFERROR(VLOOKUP(B8,Produtos_Results!$A$2:$E$22,5),"") -> 0.85714286 | D8: =IFERROR(VLOOKUP(B8,Produtos_Results!$A$3:$B$22,2,FALSE),"") -> Gerenciador de Chamadas | E8: Uso de ramais em smartphones, tablets, computadores e outros dispositivos móveis | F8: Concluído
A9: 7 | B9: R-Voip | C9: =IFERROR(VLOOKUP(B9,Produtos_Results!$A$2:$E$22,5),"") -> 0.85714286 | D9: =IFERROR(VLOOKUP(B9,Produtos_Results!$A$3:$B$22,2,FALSE),"") -> Gerenciador de Chamadas | E9: CUSTO ZERO entre matriz e filiais se estendendo para clientes e fornecedores via ramal | F9: Concluído
A10: 8 | B10: R-Voip | C10: =IFERROR(VLOOKUP(B10,Produtos_Results!$A$2:$E$22,5),"") -> 0.85714286 | D10: =IFERROR(VLOOKUP(B10,Produtos_Results!$A$3:$B$22,2,FALSE),"") -> Gerenciador de Chamadas | E10: Identificação de Chamadas | F10: Concluído
A11: 9 | B11: R-Voip | C11: =IFERROR(VLOOKUP(B11,Produtos_Results!$A$2:$E$22,5),"") -> 0.85714286 | D11: =IFERROR(VLOOKUP(B11,Produtos_Results!$A$3:$B$22,2,FALSE),"") -> Gerenciador de Chamadas | E11: URA | F11: Concluído
A12: 10 | B12: R-Voip | C12: =IFERROR(VLOOKUP(B12,Produtos_Results!$A$2:$E$22,5),"") -> 0.85714286 | D12: =IFERROR(VLOOKUP(B12,Produtos_Results!$A$3:$B$22,2,FALSE),"") -> Gerenciador de Chamadas | E12: Atendimento automático | F12: Concluído
A13: 11 | B13: R-Voip | C13: =IFERROR(VLOOKUP(B13,Produtos_Results!$A$2:$E$22,5),"") -> 0.85714286 | D13: =IFERROR(VLOOKUP(B13,Produtos_Results!$A$3:$B$22,2,FALSE),"") -> Gerenciador de Chamadas | E13: Envio de SMS | F13: Concluído
A14: 12 | B14: R-Voip | C14: =IFERROR(VLOOKUP(B14,Produtos_Results!$A$2:$E$22,5),"") -> 0.85714286 | D14: =IFERROR(VLOOKUP(B14,Produtos_Results!$A$3:$B$22,2,FALSE),"") -> Gerenciador de Chamadas | E14: Redirecionamento de Chamadas | F14: Concluído
A15: 13 | B15: R-Voip | C15: =IFERROR(VLOOKUP(B15,Produtos_Results!$A$2:$E$22,5),"") -> 0.85714286 | D15: =IFERROR(VLOOKUP(B15,Produtos_Results!$A$3:$B$22,2,FALSE),"") -> Gerenciador de Chamadas | E15: Correio de Voz | F15: Concluído
A16: 14 | B16: R-Voip | C16: =IFERROR(VLOOKUP(B16,Produtos_Results!$A$2:$E$22,5),"") -> 0.85714286 | D16: =IFERROR(VLOOKUP(B16,Produtos_Results!$A$3:$B$22,2,FALSE),"") -> Gerenciador de Chamadas | E16: Sala de Conferência | F16: Concluído
A17: 15 | B17: R-Voip | C17: =IFERROR(VLOOKUP(B17,Produtos_Results!$A$2:$E$22,5),"") -> 0.85714286 | D17: =IFERROR(VLOOKUP(B17,Produtos_Results!$A$3:$B$22,2,FALSE),"") -> Gerenciador de Chamadas | E17: Integração com Sites | F17: Concluído
A18: 16 | B18: R-Voip | C18: =IFERROR(VLOOKUP(B18,Produtos_Results!$A$2:$E$22,5),"") -> 0.85714286 | D18: =IFERROR(VLOOKUP(B18,Produtos_Results!$A$3:$B$22,2,FALSE),"") -> Gerenciador de Chamadas | E18: Integração com plataformas de mensagem instantânias (Whatsapp, Telegram, etc..) | F18: Andamento
... A125: 123 | B125: RIA | C125: =IFERROR(VLOOKUP(B125,Produtos_Results!$A$2:$E$22,5),"") -> 0 | D125: =IFERROR(VLOOKUP(B125,Produtos_Results!$A$3:$B$22,2,FALSE),"") -> Plataforma de Inteligencial Artificial | E125: Verificação dos processos | F125: Pendente
A126: 124 | C126: =IFERROR(VLOOKUP(B126,Produtos_Results!$A$2:$E$22,5),"") | D126: =IFERROR(VLOOKUP(B126,Produtos_Results!$A$3:$B$22,2,FALSE),"")
A127: 125 | C127: =IFERROR(VLOOKUP(B127,Produtos_Results!$A$2:$E$22,5),"") | D127: =IFERROR(VLOOKUP(B127,Produtos_Results!$A$3:$B$22,2,FALSE),"")
A128: 126 | C128: =IFERROR(VLOOKUP(B128,Produtos_Results!$A$2:$E$22,5),"") | D128: =IFERROR(VLOOKUP(B128,Produtos_Results!$A$3:$B$22,2,FALSE),"")
A129: 127 | C129: =IFERROR(VLOOKUP(B129,Produtos_Results!$A$2:$E$22,5),"") | D129: =IFERROR(VLOOKUP(B129,Produtos_Results!$A$3:$B$22,2,FALSE),"")
A130: 128 | C130: =IFERROR(VLOOKUP(B130,Produtos_Results!$A$2:$E$22,5),"") | D130: =IFERROR(VLOOKUP(B130,Produtos_Results!$A$3:$B$22,2,FALSE),"")
A131: 129 | C131: =IFERROR(VLOOKUP(B131,Produtos_Results!$A$2:$E$22,5),"") | D131: =IFERROR(VLOOKUP(B131,Produtos_Results!$A$3:$B$22,2,FALSE),"")
A132: 130 | C132: =IFERROR(VLOOKUP(B132,Produtos_Results!$A$2:$E$22,5),"") | D132: =IFERROR(VLOOKUP(B132,Produtos_Results!$A$3:$B$22,2,FALSE),"")
A133: 131 | C133: =IFERROR(VLOOKUP(B133,Produtos_Results!$A$2:$E$22,5),"") | D133: =IFERROR(VLOOKUP(B133,Produtos_Results!$A$3:$B$22,2,FALSE),"")
A134: 132 | C134: =IFERROR(VLOOKUP(B134,Produtos_Results!$A$2:$E$22,5),"") | D134: =IFERROR(VLOOKUP(B134,Produtos_Results!$A$3:$B$22,2,FALSE),"")
A135: 133 | C135: =IFERROR(VLOOKUP(B135,Produtos_Results!$A$2:$E$22,5),"") | D135: =IFERROR(VLOOKUP(B135,Produtos_Results!$A$3:$B$22,2,FALSE),"")
A136: 134 | C136: =IFERROR(VLOOKUP(B136,Produtos_Results!$A$2:$E$22,5),"") | D136: =IFERROR(VLOOKUP(B136,Produtos_Results!$A$3:$B$22,2,FALSE),"")
A137: 135 | C137: =IFERROR(VLOOKUP(B137,Produtos_Results!$A$2:$E$22,5),"") | D137: =IFERROR(VLOOKUP(B137,Produtos_Results!$A$3:$B$22,2,FALSE),"")
... A152: 150 | C152: =IFERROR(VLOOKUP(B152,Produtos_Results!$A$2:$E$22,5),"") | D152: =IFERROR(VLOOKUP(B152,Produtos_Results!$A$3:$B$22,2,FALSE),"")

Sheet Tabela_Requisitos_Negocio
A1: Principais Requisitos de Negócio
A2: ID | B2: Requisito
A3: 1 | B3: Aumentar a Retenção de Clientes
A4: 2 | B4: Identificar gargalos na Cadeira Produtiva
A5: 3 | B5: Diminuir riscos operacionais
A6: 4 | B6: Melhorar a Experiência do Cliente c/ Ominichannel
A7: 5 | B7: Implementar Dashboard com KPI's do negocio
A9: Total | B9: =count(A3:A7) -> 5

Sheet BigNumbers
A1: Big Numbers - Padaria 4.0
A2: Item | B2: Valor | C2: Descrição
A3: Total de Requisitos de Negócio | B3: =COUNT(Tabela_Requisitos_Negocio!A3:A7) -> 5 | C3: Total de Requisitos de Negócios definidos como estratégicos a partir do Canvas
A4: Total de Produtos | B4: =COUNTA(Produtos_Results!A3:A22) -> 14 | C4: Total de Produtos Results
A5: Total de Funcionalidades | B5: =COUNTA(Produtos_X_Funcionalidades!E2:E152) -> 124 | C5: Total das Funcionalidades de todos os Produtos
A6: Total de Requisitos Técnicos | B6: =COUNTA(BluePrint!$C$3:$C$72) -> 41
A7: Total de Produtos Classificado como Quick Wins | B7: =COUNTIF(BluePrint!$I$3:$I$72,"4-Quick Wins") -> 18 | C7: Classificado com Quick Wins Requisitos Técnicos Urgentes para MVP
A8: Total de Produtos Classificado como Short Term | B8: =COUNTIF(BluePrint!$I$3:$I$72,"3-Short Term") -> 8
A9: Total de Produtos Classificado como Medium Term | B9: =COUNTIF(BluePrint!$I$3:$I$72,"2-Medium Term") -> 3
A10: Total de Produtos Classificado como Extend Term | B10: =COUNTIF(BluePrint!$I$3:$I$72,"1-Extend Term") -> 12
A11: Percentual Minimo para Produto Pronto | B11: =80/100 -> 0.8 | C11: Definido percentual mínimo para um produto já esta no seu nivel de excelência
A12: Total de Produtos Prontos (<80%) | B12: =COUNTIF(Produtos_Results!E3:E22,CONCATENATE(">",B11)) -> 2 | C12: Conta total de Produtos com nível de excelencia minimo
A13: Nível de Eficiência dos Produtos | B13: =B12/B4 -> 0.14285714 | C13: Total de Produtos X Produtos Finalizados
A14: Funcionalidades OK | B14: =COUNTIF(Produtos_X_Funcionalidades!F2:F150,"Concluído") -> 37 | C14: Total de Funcionalidades com Status de Concluído.
A15: Nível de Eficiência das Funcionalidades | B15: =B14/B5 -> 0.2983871 | C15: Nível de Eficiência das funcionalidades
D44: =C46 -> 0.16666667 | E44: =D44*24 -> 4
B46: 0.16666667 | C46: =TIMEVALUE(B46) -> 0.16666667
B47: =E44*60 -> 240 | C47: =DATEVALUE(B46)*60 -> 0
B48: =85/B47 -> 0.35416667
B49: =B48*60 -> 21.25 | D49: 21.25
D50: 21.25
D51: 21.25
D52: 21.25

Sheet Exemplo Canvas DropBox

Sheet CANVAS
A1: Parceiros | B1: Atividades-Chave | C1: Proposições de Valor | D1: Relacionamento com os Clientes | E1: Segmentos de Clientes
A2: ='8-Parcerias Chave'!A14 -> Fabricas de Software | B2: ='7-Atividades Chave'!A14 -> Treinamento da Rede | C2: ='2-Proposições de Valor'!A14 -> Padaria: | D2: ='4-Relacionamento com Clientes'!A14 -> Ações de Marketing | E2: ='1-Segmentos de Clientes'!A14 -> Padarias
A3: ='8-Parcerias Chave'!A15 -> Data Centers | B3: ='7-Atividades Chave'!A15 -> Desenvolvimento de Software | C3: ='2-Proposições de Valor'!A15 -> Identificar a jornada, hábitos e prefrências dos clientes | D3: ='4-Relacionamento com Clientes'!A15 -> Eventos para Canais (Results Summit) | E3: ='1-Segmentos de Clientes'!A15
A4: ='8-Parcerias Chave'!A16 -> Parceiros de Backoffice (Contabilidade, Juridico etc..) | B4: ='7-Atividades Chave'!A16 -> Ações de Marketing | C4: ='2-Proposições de Valor'!A16 -> Mapear as demandas de maneira perzonalizada | D4: ='4-Relacionamento com Clientes'!A16 -> Webinars | E4: ='1-Segmentos de Clientes'!A16
A5: ='8-Parcerias Chave'!A17 -> Associações (Abip, Sampapão, Rio+Pão, Sebrae, etc..) | B5: ='7-Atividades Chave'!A17 -> Backoffice (contabilidade, financeiro, etc..) | C5: ='2-Proposições de Valor'!A17 -> Monitorar os pedidos, produção, produtos e entrega | D5: ='4-Relacionamento com Clientes'!A17 -> Banners nas Padarias | E5: ='1-Segmentos de Clientes'!A17
A6: ='8-Parcerias Chave'!A18 -> Agencias de Marketing e Publicidade | B6: ='7-Atividades Chave'!A18 -> Monitoramento de dados e sistemas | C6: ='2-Proposições de Valor'!A18 -> Detectar e corrigir falhas nos equipamentos e sistemas | D6: ='4-Relacionamento com Clientes'!A18 -> Workshops de Harmonização | E6: ='1-Segmentos de Clientes'!A18
A7: ='8-Parcerias Chave'!A19 -> Rede de Distribuidores | B7: ='7-Atividades Chave'!A19 -> Atendimento/Suporte ao Cliente | C7: ='2-Proposições de Valor'!A19 -> Agilizar a comunicação com clientes, fornecedores e colaboradores | D7: ='4-Relacionamento com Clientes'!A19 -> Atendimento (Call Center) | E7: ='1-Segmentos de Clientes'!A19
A8: ='8-Parcerias Chave'!A20 -> Investidores | B8: ='7-Atividades Chave'!A20 -> Comercial | C8: ='2-Proposições de Valor'!A20 -> Identificar possíveis furtos, perdas e desperdícios | D8: ='4-Relacionamento com Clientes'!A20 | E8: ='1-Segmentos de Clientes'!A20
A9: ='8-Parcerias Chave'!A21 -> Universidades (USP, FEI etc..) | B9: ='7-Atividades Chave'!A21 -> P&D | C9: ='2-Proposições de Valor'!A21 | D9: ='4-Relacionamento com Clientes'!A21 | E9: ='1-Segmentos de Clientes'!A21
A10: ='8-Parcerias Chave'!A22 -> Lianja | B10: ='7-Atividades Chave'!A22 | C10: ='2-Proposições de Valor'!A22 -> Clientes: | D10: ='4-Relacionamento com Clientes'!A22 | E10: ='1-Segmentos de Clientes'!A22
A11: ='8-Parcerias Chave'!A23 -> Consultorias e Mentorias | B11: ='7-Atividades Chave'!A23 | C11: ='2-Proposições de Valor'!A23 -> Pesquisar produtos on-line | D11: ='4-Relacionamento com Clientes'!A23 | E11: ='1-Segmentos de Clientes'!A23
A12: ='8-Parcerias Chave'!A24 -> Padaria Piloto | B12: Recursos-Chave | C12: ='2-Proposições de Valor'!A24 -> Compra e pagamento via aplicativos | D12: Canais | E12: ='1-Segmentos de Clientes'!A24
A13: ='8-Parcerias Chave'!A25 | B13: ='6-Recursos Chave'!A14 -> Desenvolvedores Polivalente (Java, Phyton etc..) | C13: ='2-Proposições de Valor'!A25 -> Atendimento personalizado | D13: ='3-Canais'!A14 -> Appliance com Solução Embarcada | E13: ='1-Segmentos de Clientes'!A25
A14: ='8-Parcerias Chave'!A26 | B14: ='6-Recursos Chave'!A15 -> Especialistas de UX | C14: ='2-Proposições de Valor'!A26 -> Efetuar pedido por diferentes canais de comunicação | D14: ='3-Canais'!A15 -> Plataforma com Multi-Aplicativos local ou Nuvem | E14: ='1-Segmentos de Clientes'!A26
A15: ='8-Parcerias Chave'!A27 | B15: ='6-Recursos Chave'!A16 -> Equipamentos Eletronicos para IoT | C15: ='2-Proposições de Valor'!A27 -> Acompanhar o status do pedido | D15: ='3-Canais'!A16 -> Revenda feitas por Parceiros Estratégicos | E15: ='1-Segmentos de Clientes'!A27
A16: ='8-Parcerias Chave'!A28 | B16: ='6-Recursos Chave'!A17 -> Serviços em Nuvem | C16: ='2-Proposições de Valor'!A28 | D16: ='3-Canais'!A17 -> Sindicatos das Padarias | E16: ='1-Segmentos de Clientes'!A28
A17: ='8-Parcerias Chave'!A29 | B17: ='6-Recursos Chave'!A18 -> Logistica (movimentação de Hardware) | C17: ='2-Proposições de Valor'!A29 | D17: ='3-Canais'!A18 -> Eventos do Segmento (Feiras, Workshops etc..) | E17: ='1-Segmentos de Clientes'!A29
A18: ='8-Parcerias Chave'!A30 | B18: ='6-Recursos Chave'!A19 -> Atendimento Vendas e Suporte Tecnico | C18: ='2-Proposições de Valor'!A30 | D18: ='3-Canais'!A19 -> Sites | E18: ='1-Segmentos de Clientes'!A30
A19: ='8-Parcerias Chave'!A31 | B19: ='6-Recursos Chave'!A20 -> Atendimento Rede de Distribuidores | C19: ='2-Proposições de Valor'!A31 | D19: ='3-Canais'!A20 -> WhatsApp | E19: ='1-Segmentos de Clientes'!A31
A20: ='8-Parcerias Chave'!A32 | B20: ='6-Recursos Chave'!A21 -> Recursos Financeiros (Investimentos) | C20: ='2-Proposições de Valor'!A32 | D20: ='3-Canais'!A21 -> Sociais (youtube, facebook..) | E20: ='1-Segmentos de Clientes'!A32
A21: ='8-Parcerias Chave'!A33 | B21: ='6-Recursos Chave'!A22 -> Profissional de Adoção de Tecnologia | C21: ='2-Proposições de Valor'!A33 | D21: ='3-Canais'!A23 | E21: ='1-Segmentos de Clientes'!A33
A22: 9) Estrutura de Custo | D22: 5) Fontes de Receita
A23: ='9-Estrutura de Custos'!A14 -> Licenciamento | D23: ='5-Fontes de Receita'!A14 -> Plano Basico Mensal
A24: ='9-Estrutura de Custos'!A15 -> Desenvolvimento de Software | D24: ='5-Fontes de Receita'!A15 -> Plano Médio Mensal
A25: ='9-Estrutura de Custos'!A16 -> Infraestrutura | D25: ='5-Fontes de Receita'!A16 -> Plano Avançado Mensal
A26: ='9-Estrutura de Custos'!A17 -> Pessoal
A27: ='9-Estrutura de Custos'!A18 -> Backoffice (com todos parceiros)
A28: ='9-Estrutura de Custos'!A19 -> Treinamentos e Capacitação
A29: ='9-Estrutura de Custos'!A20
A30: ='9-Estrutura de Custos'!A21
A31: ='9-Estrutura de Custos'!A22
A32: ='9-Estrutura de Custos'!A23

Sheet 2-Proposições de Valor
A1: 2-Proposições de Valor
A2: Perguntas Importantes
A3: 1) Que valor nos Entregamos para os Clientes?
A4: 2) Quais problemas nos estamos ajudando resolver?
A5: 3) Que Necessidades dos Clientes que nos estamos satisfazendo?
A6: 4) Que pacotes de produtos/serviços nós estamos oferecendo para cada Segmento de Clientes?
A13: Respostas
A14: Padaria:
A15: Identificar a jornada, hábitos e prefrências dos clientes
A16: Mapear as demandas de maneira perzonalizada
A17: Monitorar os pedidos, produção, produtos e entrega
A18: Detectar e corrigir falhas nos equipamentos e sistemas
A19: Agilizar a comunicação com clientes, fornecedores e colaboradores | C19: Voltar Menu Principal
A20: Identificar possíveis furtos, perdas e desperdícios | C20: IR para o Canvas
A22: Clientes:
A23: Pesquisar produtos on-line
A24: Compra e pagamento via aplicativos
A25: Atendimento personalizado
A26: Efetuar pedido por diferentes canais de comunicação
A27: Acompanhar o status do pedido

Sheet 1-Segmentos de Clientes
A1: 1-Segmentos de Clientes
A2: Perguntas Importantes
A3: 1) Para quem estamos criando VALOR?
A4: 2) Quais são as caracteristicas destes segmentos?
A5: 3) Quem são os nossos potenciais clientes mais importantes?
A13: Respostas
A14: Padarias
C19: Voltar Menu Principal
C20: IR para o Canvas

Sheet 3-Canais
A1: 3-Canais
A2: Perguntas Importantes
A3: 1) Por quais Canais nossos Segmentos de Clientes podem/querem ser abordados?
A4: 2) Como esses Canais estão integrados?
A5: 3) Qual é o Custo/Benefício da utilização de cada Canal?
A6: 4) Como os alcançamos agora?
A13: Respostas
A14: Appliance com Solução Embarcada
A15: Plataforma com Multi-Aplicativos local ou Nuvem
A16: Revenda feitas por Parceiros Estratégicos
A17: Sindicatos das Padarias
A18: Eventos do Segmento (Feiras, Workshops etc..)
A19: Sites | C19: Voltar Menu Principal
A20: WhatsApp | C20: IR para o Canvas
A21: Sociais (youtube, facebook..)
A22: Distribuidores

Sheet 4-Relacionamento com Clientes
A1: 4-Relacionamento com Clientes
A2: Perguntas Importantes
A3: 1) Que tipo de relacionamento os clientes de cada segmento podem esperar?
A4: 2) Qual é o custo de cada um deles?
A5: 3) Como isso está integrado ao Modelo de Negócio como um todo?
A6: 4) O que pode se esperar em termos de aquisição e retenção para esse tipo de relacionamento?
A13: Respostas
A14: Ações de Marketing
A15: Eventos para Canais (Results Summit)
A16: Webinars
A17: Banners nas Padarias
A18: Workshops de Harmonização
A19: Atendimento (Call Center) | C19: Voltar Menu Principal
C20: IR para o Canvas

Sheet 5-Fontes de Receita
A1: 5-Fontes de Receita
A2: Perguntas Importantes
A3: 1) O que o cliente valoriza e pelo qual está disposto a pagar?
A4: 2) O que eles têm pago ultimamente para resolver o mesmo problema?
A5: 3) De que maneira eles preferem pagar pelo valor gerado?
A6: 4) Qual é a parcela de contribuição de cada fonte de receita para a receita total esperada?
A13: Respostas
A14: Plano Basico Mensal
A15: Plano Médio Mensal
A16: Plano Avançado Mensal
C19: Voltar Menu Principal
C20: IR para o Canvas

Sheet 6-Recursos Chave
A1: 6-Recursos-Chave
A2: Perguntas Importantes
A3: 1) Que Recursos-Chave são importantes para a nossa proposição de valor?
A4: 2) Para sustentar os Canais?
A5: 3) Para manter o Relacionamentos com os Clientes?
A6: 4) Para implementar(alcançar) as Fontes de Receita?
A13: Respostas
A14: Desenvolvedores Polivalente (Java, Phyton etc..)
A15: Especialistas de UX
A16: Equipamentos Eletronicos para IoT
A17: Serviços em Nuvem
A18: Logistica (movimentação de Hardware)
A19: Atendimento Vendas e Suporte Tecnico | C19: Voltar Menu Principal
A20: Atendimento Rede de Distribuidores | C20: IR para o Canvas
A21: Recursos Financeiros (Investimentos)
A22: Profissional de Adoção de Tecnologia
A23: Departamento de SAC/Ouvidoria
A24: BackOffice
A25: Marketing

Sheet 7-Atividades Chave
A1: 7-Atividades-Chave
A2: Perguntas Importantes
A3: 1) Que Atividades-Chave são importantes para a nossa proposição de valor?
A4: 2) Para sustentar os Canais?
A5: 3) Para manter o Relacionamentos com os Clientes?
A6: 4) Para implementar(alcançar) as Fontes de Receita?
A13: Respostas
A14: Treinamento da Rede
A15: Desenvolvimento de Software
A16: Ações de Marketing
A17: Backoffice (contabilidade, financeiro, etc..)
A18: Monitoramento de dados e sistemas
A19: Atendimento/Suporte ao Cliente | C19: Voltar Menu Principal
A20: Comercial | C20: IR para o Canvas
A21: P&D

Sheet 8-Parcerias Chave
A1: 8-Parcerias Chave
A2: Perguntas Importantes
A3: 1) Quais devem ser nossos parceiros-chave?
A4: 2) Quem são os fornecedores estratégicos?
A5: 3) Quais recursos-chave estamos obtendo deles?
A6: 4) E quais atividades-chave eles produzem?
A13: Respostas
A14: Fabricas de Software
A15: Data Centers
A16: Parceiros de Backoffice (Contabilidade, Juridico etc..)
A17: Associações (Abip, Sampapão, Rio+Pão, Sebrae, etc..)
A18: Agencias de Marketing e Publicidade
A19: Rede de Distribuidores | C19: Voltar Menu Principal
A20: Investidores | C20: IR para o Canvas
A21: Universidades (USP, FEI etc..)
A22: Lianja
A23: Consultorias e Mentorias
A24: Padaria Piloto

Sheet 9-Estrutura de Custos
A1: 9-Estrutura de Custos
A2: Perguntas Importantes
A3: 1) Quais são os custos mais importantes inerentes ao nosso modelo de negócio?
A4: 2) Quais recursos-chave são os mais caros?
A5: 3) Quais atividades-chave são as mais caras?
A6: 4) Quais dos custos são Variaveis e quais são Fixos?
A13: Respostas
A14: Licenciamento
A15: Desenvolvimento de Software
A16: Infraestrutura
A17: Pessoal
A18: Backoffice (com todos parceiros)
A19: Treinamentos e Capacitação | C19: Voltar Menu Principal
C20: IR para o Canvas

Sheet 10-VersãoCanvas

Sheet Canvas-como-5w2h

Sheet Historico_Reuniões
A1: Historico das Reuniões
A2: Id | B2: Data | C2: Descrição | D2: Quem
A3: 1 | B3: 43892 | C3: Implantar do Sistema 2,5 Padarias por Semana | D3: Paulo
A4: 2 | B4: 43892 | C4: Life time de 8 meses | D4: Jefferson
A5: 3 | B5: 43892 | C5: Criar KPIs para monitorar o Sucesso do Cliente | D5: Tom
A6: 4 | B6: 43892 | C6: Mais que uma Solução... um desenvolvimento de um Mercado | D6: Paulo
A7: 5 | B7: 43892 | C7: Temos que pensar como um Fabricante... Distribuidor para a entrega para Padaria
A8: 6
A9: 7
A10: 8
A11: 9
A12: 10
A13: 11
A14: 12
A15: 13
A16: 14
A17: 15
A18: 16
A19: 17
... A28: 26
